2018-03-18 17:31:06,295 ERROR: Exception on /index [GET] [in /Users/nielsenz/flaskNotes/lib/python3.6/site-packages/flask/app.py:1560]
Traceback (most recent call last):
  File "/Users/nielsenz/flaskNotes/lib/python3.6/site-packages/flask/app.py", line 1982, in wsgi_app
    response = self.full_dispatch_request()
  File "/Users/nielsenz/flaskNotes/lib/python3.6/site-packages/flask/app.py", line 1614, in full_dispatch_request
    rv = self.handle_user_exception(e)
  File "/Users/nielsenz/flaskNotes/lib/python3.6/site-packages/flask/app.py", line 1517, in handle_user_exception
    reraise(exc_type, exc_value, tb)
  File "/Users/nielsenz/flaskNotes/lib/python3.6/site-packages/flask/_compat.py", line 33, in reraise
    raise value
  File "/Users/nielsenz/flaskNotes/lib/python3.6/site-packages/flask/app.py", line 1612, in full_dispatch_request
    rv = self.dispatch_request()
  File "/Users/nielsenz/flaskNotes/lib/python3.6/site-packages/flask/app.py", line 1598, in dispatch_request
    return self.view_functions[rule.endpoint](**req.view_args)
  File "/Users/nielsenz/flaskNotes/lib/python3.6/site-packages/flask_login/utils.py", line 261, in decorated_view
    return func(*args, **kwargs)
  File "/Users/nielsenz/flaskNotes/app/routes.py", line 31, in index
    prev_url=prev_url)
  File "/Users/nielsenz/flaskNotes/lib/python3.6/site-packages/flask/templating.py", line 134, in render_template
    context, ctx.app)
  File "/Users/nielsenz/flaskNotes/lib/python3.6/site-packages/flask/templating.py", line 116, in _render
    rv = template.render(context)
  File "/Users/nielsenz/flaskNotes/lib/python3.6/site-packages/jinja2/asyncsupport.py", line 76, in render
    return original_render(self, *args, **kwargs)
  File "/Users/nielsenz/flaskNotes/lib/python3.6/site-packages/jinja2/environment.py", line 1008, in render
    return self.environment.handle_exception(exc_info, True)
  File "/Users/nielsenz/flaskNotes/lib/python3.6/site-packages/jinja2/environment.py", line 780, in handle_exception
    reraise(exc_type, exc_value, tb)
  File "/Users/nielsenz/flaskNotes/lib/python3.6/site-packages/jinja2/_compat.py", line 37, in reraise
    raise value.with_traceback(tb)
  File "/Users/nielsenz/flaskNotes/app/templates/index.html", line 2, in top-level template code
    {% import 'bootstrap/wtf.html' as wtf %}
  File "/Users/nielsenz/flaskNotes/app/templates/base.html", line 1, in top-level template code
    {% extends 'bootstrap/base.html' %}
  File "/Users/nielsenz/flaskNotes/lib/python3.6/site-packages/flask_bootstrap/templates/bootstrap/base.html", line 1, in top-level template code
    {% block doc -%}
  File "/Users/nielsenz/flaskNotes/lib/python3.6/site-packages/flask_bootstrap/templates/bootstrap/base.html", line 4, in block "doc"
    {%- block html %}
  File "/Users/nielsenz/flaskNotes/lib/python3.6/site-packages/flask_bootstrap/templates/bootstrap/base.html", line 20, in block "html"
    {% block body -%}
  File "/Users/nielsenz/flaskNotes/lib/python3.6/site-packages/flask_bootstrap/templates/bootstrap/base.html", line 23, in block "body"
    {% block content -%}
  File "/Users/nielsenz/flaskNotes/app/templates/base.html", line 46, in block "content"
    {% block app_content %}{% endblock %}
  File "/Users/nielsenz/flaskNotes/app/templates/index.html", line 11, in block "app_content"
    {% include '_post.html' %}
  File "/Users/nielsenz/flaskNotes/app/templates/_post.html", line 12, in top-level template code
    {{ note.html() }}
  File "/Users/nielsenz/flaskNotes/app/models.py", line 64, in html
    urlize_all=True)
  File "/Users/nielsenz/flaskNotes/lib/python3.6/site-packages/micawber/parsers.py", line 129, in parse_html
    raise Exception('Unable to parse HTML, please install BeautifulSoup '
Exception: Unable to parse HTML, please install BeautifulSoup or beautifulsoup4, or use the text parser
2018-03-18 17:32:06,383 INFO: Microblog startup [in /Users/nielsenz/flaskNotes/app/__init__.py:51]
2018-03-18 17:37:15,195 INFO: Microblog startup [in /Users/nielsenz/flaskNotes/app/__init__.py:51]
2018-03-18 18:05:31,438 INFO: Microblog startup [in /Users/nielsenz/flaskNotes/app/__init__.py:51]
2018-03-18 18:06:22,512 INFO: Microblog startup [in /Users/nielsenz/flaskNotes/app/__init__.py:51]
2018-03-18 18:07:14,609 INFO: Microblog startup [in /Users/nielsenz/flaskNotes/app/__init__.py:51]
2018-03-18 18:09:27,731 INFO: Microblog startup [in /Users/nielsenz/flaskNotes/app/__init__.py:51]
2018-03-18 18:15:36,022 INFO: Microblog startup [in /Users/nielsenz/flaskNotes/app/__init__.py:51]
2018-03-18 18:18:04,888 INFO: Microblog startup [in /Users/nielsenz/flaskNotes/app/__init__.py:51]
2018-03-18 18:18:11,297 ERROR: Exception on /index [GET] [in /Users/nielsenz/flaskNotes/lib/python3.6/site-packages/flask/app.py:1560]
Traceback (most recent call last):
  File "/Users/nielsenz/flaskNotes/lib/python3.6/site-packages/flask/app.py", line 1982, in wsgi_app
    response = self.full_dispatch_request()
  File "/Users/nielsenz/flaskNotes/lib/python3.6/site-packages/flask/app.py", line 1614, in full_dispatch_request
    rv = self.handle_user_exception(e)
  File "/Users/nielsenz/flaskNotes/lib/python3.6/site-packages/flask/app.py", line 1517, in handle_user_exception
    reraise(exc_type, exc_value, tb)
  File "/Users/nielsenz/flaskNotes/lib/python3.6/site-packages/flask/_compat.py", line 33, in reraise
    raise value
  File "/Users/nielsenz/flaskNotes/lib/python3.6/site-packages/flask/app.py", line 1612, in full_dispatch_request
    rv = self.dispatch_request()
  File "/Users/nielsenz/flaskNotes/lib/python3.6/site-packages/flask/app.py", line 1598, in dispatch_request
    return self.view_functions[rule.endpoint](**req.view_args)
  File "/Users/nielsenz/flaskNotes/lib/python3.6/site-packages/flask_login/utils.py", line 261, in decorated_view
    return func(*args, **kwargs)
  File "/Users/nielsenz/flaskNotes/app/routes.py", line 23, in index
    notes = current_user.followed_posts().paginate(
  File "/Users/nielsenz/flaskNotes/app/models.py", line 32, in followed_posts
    return own.order_by(Note.timestamp.desc()).where(Note.archived == False)
AttributeError: 'BaseQuery' object has no attribute 'where'
2018-03-18 18:21:31,757 INFO: Microblog startup [in /Users/nielsenz/flaskNotes/app/__init__.py:51]
2018-03-18 18:21:37,203 ERROR: Exception on /index [POST] [in /Users/nielsenz/flaskNotes/lib/python3.6/site-packages/flask/app.py:1560]
Traceback (most recent call last):
  File "/Users/nielsenz/flaskNotes/lib/python3.6/site-packages/flask/app.py", line 1982, in wsgi_app
    response = self.full_dispatch_request()
  File "/Users/nielsenz/flaskNotes/lib/python3.6/site-packages/flask/app.py", line 1614, in full_dispatch_request
    rv = self.handle_user_exception(e)
  File "/Users/nielsenz/flaskNotes/lib/python3.6/site-packages/flask/app.py", line 1517, in handle_user_exception
    reraise(exc_type, exc_value, tb)
  File "/Users/nielsenz/flaskNotes/lib/python3.6/site-packages/flask/_compat.py", line 33, in reraise
    raise value
  File "/Users/nielsenz/flaskNotes/lib/python3.6/site-packages/flask/app.py", line 1612, in full_dispatch_request
    rv = self.dispatch_request()
  File "/Users/nielsenz/flaskNotes/lib/python3.6/site-packages/flask/app.py", line 1598, in dispatch_request
    return self.view_functions[rule.endpoint](**req.view_args)
  File "/Users/nielsenz/flaskNotes/lib/python3.6/site-packages/flask_login/utils.py", line 261, in decorated_view
    return func(*args, **kwargs)
  File "/Users/nielsenz/flaskNotes/app/routes.py", line 23, in index
    notes = current_user.followed_posts().paginate(
  File "/Users/nielsenz/flaskNotes/app/models.py", line 32, in followed_posts
    return own.order_by(Note.timestamp.desc()).filter_by(Note.archived == False)
TypeError: filter_by() takes 1 positional argument but 2 were given
2018-03-18 18:21:38,550 ERROR: Exception on /index [GET] [in /Users/nielsenz/flaskNotes/lib/python3.6/site-packages/flask/app.py:1560]
Traceback (most recent call last):
  File "/Users/nielsenz/flaskNotes/lib/python3.6/site-packages/flask/app.py", line 1982, in wsgi_app
    response = self.full_dispatch_request()
  File "/Users/nielsenz/flaskNotes/lib/python3.6/site-packages/flask/app.py", line 1614, in full_dispatch_request
    rv = self.handle_user_exception(e)
  File "/Users/nielsenz/flaskNotes/lib/python3.6/site-packages/flask/app.py", line 1517, in handle_user_exception
    reraise(exc_type, exc_value, tb)
  File "/Users/nielsenz/flaskNotes/lib/python3.6/site-packages/flask/_compat.py", line 33, in reraise
    raise value
  File "/Users/nielsenz/flaskNotes/lib/python3.6/site-packages/flask/app.py", line 1612, in full_dispatch_request
    rv = self.dispatch_request()
  File "/Users/nielsenz/flaskNotes/lib/python3.6/site-packages/flask/app.py", line 1598, in dispatch_request
    return self.view_functions[rule.endpoint](**req.view_args)
  File "/Users/nielsenz/flaskNotes/lib/python3.6/site-packages/flask_login/utils.py", line 261, in decorated_view
    return func(*args, **kwargs)
  File "/Users/nielsenz/flaskNotes/app/routes.py", line 23, in index
    notes = current_user.followed_posts().paginate(
  File "/Users/nielsenz/flaskNotes/app/models.py", line 32, in followed_posts
    return own.order_by(Note.timestamp.desc()).filter_by(Note.archived == False)
TypeError: filter_by() takes 1 positional argument but 2 were given
2018-03-18 18:23:01,050 INFO: Microblog startup [in /Users/nielsenz/flaskNotes/app/__init__.py:51]
